<?xml version="1.0" encoding="utf-8"?>

<robot name="basic_link">

    <link name="world">
    </link>

    <joint name="world_to_base_link" type="fixed">
        <parent link="world"/>
        <child link="base_link"/>
        <origin xyz="0.0 0.0 0.0" rpy="0.0 0.0 0.0"/>
    </joint>
    
    <link name="base_link">
        <!-- Descripción de la parte visual del eslabón -->
        <visual>
            <!-- Posición y orientación de origen del eslabón -->
            <origin xyz="0.0 0.0 0.075" rpy="0.0 0.0 0.0"/>
            <!-- Definición de la geometría del eslabón -->
            <geometry>
                <box size="0.1 0.12 0.15"/>             
            </geometry>
            <!-- Definición del color del eslabón -->
            <material name="grey">
                <color rgba="0.5 0.5 0.5 1.0" />
            </material>      
        </visual>
        <!-- Descripción de las relaciones de colisión -->
        <collision>
            <!-- Posición y orientación de origen del eslabón -->
            <origin xyz="0.0 0.0 0.075" rpy="0.0 0.0 0.0"/>
            <!-- Definición de la geometría del eslabón -->
            <geometry>
                <box size="0.1 0.12 0.15"/>             
            </geometry>          
        </collision>
        <!-- Descripción de la inercia del eslabón -->
        <inertial>
            <!-- Masa del eslabón -->
            <mass value="0.5"/>
            <!-- Ubicación del sistema inercial asociado al centro de masa -->
            <origin xyz="0.0 0.0 0.0" rpy="0.0 0.0 0.0"/>
            <!-- Matriz de inercia en el centro de masa -->
            <inertia ixx="0.1" ixy="0.0" ixz="0.0" iyy="1.0" iyz="0.0" izz="1.0"/> 
        </inertial>
    </link>

    <link name="link_1">
        <!-- Descripción de la parte visual del eslabón -->
        <visual>
            <!-- Posición y orientación de origen del eslabón -->
            <origin xyz="0.025 0.0 0.25" rpy="0.0 0.0 0.0"/>
            <!-- Definición de la geometría del eslabón -->
            <geometry>
                <box size="0.05 0.05 0.5"/>             
            </geometry>
            <!-- Definición del color del eslabón -->
            <material name="red">
                <color rgba="0.5 0.0 0.0 1.0" />
            </material>      
        </visual>
        <!-- Descripción de las relaciones de colisión -->
        <collision>
            <!-- Posición y orientación de origen del eslabón -->
            <origin xyz="0.025 0.0 0.25" rpy="0.0 0.0 0.0"/>
            <!-- Definición de la geometría del eslabón -->
            <geometry>
                <box size="0.05 0.05 0.5"/>             
            </geometry>          
        </collision>
        <!-- Descripción de la inercia del eslabón -->
        <inertial>
            <!-- Masa del eslabón -->
            <mass value="0.3"/>
            <!-- Ubicación del sistema inercial asociado al centro de masa -->
            <origin xyz="0.0 0.0 0.0" rpy="0.0 0.0 0.0"/>
            <!-- Matriz de inercia en el centro de masa -->
            <inertia ixx="0.1" ixy="0.0" ixz="0.0" iyy="1.0" iyz="0.0" izz="1.0"/> 
        </inertial>
    </link>

   <joint name="base_link_to_link_1" type="revolute">
    <parent link="base_link"/>
    <child link="link_1"/>
    <axis xyz="1 0 0"/>
    <limit lower="-3.14159" upper="3.14159" velocity="50.0" effort="1000.0"/>
    <origin xyz="0.05 0 0.15" rpy="0 0 0"/>
   </joint>

    <!-- Agregar tercer eslabón (link_2) -->
    <link name="link_2">
        <visual>
            <origin xyz="0.0 0.0 0.25" rpy="0.0 0.0 0.0"/>
            <geometry>
                <box size="0.05 0.05 0.5"/>
            </geometry>
            <material name="blue">
                <color rgba="0.0 0.0 0.5 1.0"/>
            </material>
        </visual>
        <collision>
            <origin xyz="0.0 0.0 0.25" rpy="0.0 0.0 0.0"/>
            <geometry>
                <box size="0.05 0.05 0.5"/>
            </geometry>
        </collision>
        <inertial>
            <mass value="0.2"/>
            <origin xyz="0.0 0.0 0.0" rpy="0.0 0.0 0.0"/>
            <inertia ixx="0.1" ixy="0.0" ixz="0.0" iyy="1.0" iyz="0.0" izz="1.0"/> 
        </inertial>
    </link>

    <!-- Junta revoluta que conecta link_1 a link_2 -->
    <joint name="link_1_to_link_2" type="revolute">
        <parent link="link_1"/>
        <child link="link_2"/>
        <axis xyz="0 1 0"/>
        <limit lower="-1.57" upper="1.57" velocity="2.0" effort="50.0"/>
        <origin xyz="0.0 0.0 0.5" rpy="0 0 0"/>
    </joint>

    <!-- Definición en Gazebo -->
    <gazebo reference="base_link">
        <material>Gazebo/Grey</material>
    </gazebo>

    <gazebo reference="link_1">
        <material>Gazebo/Red</material>
    </gazebo>

    <gazebo reference="link_2">
        <material>Gazebo/Blue</material>
    </gazebo>

    <!-- Fin de la definición de Gazebo -->

    <!-- Definición del control -->

    <transmission name ="trans_1">
        <type>transmission_interface/SimpleTransmission</type>
        <joint name="base_link_to_link_1">
            <hardwareInterface>hardware_interface/PositionJointInterface</hardwareInterface>
        </joint>
        <actuator name="motor_1">
            <hardwareInterface>hardware_interface/PositionJointInterface</hardwareInterface>
            <mechanicalReduction>1</mechanicalReduction>
        </actuator>
    </transmission>

    <transmission name ="trans_2">
        <type>transmission_interface/SimpleTransmission</type>
        <joint name="link_1_to_link_2">
            <hardwareInterface>hardware_interface/PositionJointInterface</hardwareInterface>
        </joint>
        <actuator name="motor_2">
            <hardwareInterface>hardware_interface/PositionJointInterface</hardwareInterface>
            <mechanicalReduction>1</mechanicalReduction>
        </actuator>
    </transmission>

    <gazebo>
        <plugin name="joint_state_publisher_controller"
                filename="libgazebo_ros_joint_state_publisher.so">
            <update_rate>10</update_rate>
            <joint_name>base_link_to_link_1</joint_name>
            <joint_name>link_1_to_link_2</joint_name>
        </plugin>
    </gazebo>

    <gazebo>
        <plugin name="joint_pose_trajectory_controller"
                filename="libgazebo_ros_joint_pose_trajectory.so">
            <update_rate>2</update_rate>
        </plugin>
    </gazebo>

    <!-- Fin de la definición del control -->

</robot>
